Workbook

Sheet Actual P&L
F1: Exercise:
A2: The Controller Academy | F2: 1. Bring in the budget numbers to this tab, from the Budget tab
A3: Spa Booker | F3: 2. Perform a fluctuation analysis both in dollars and % change
A4: Profit and Loss | F4: 3. Check the answer key to see you've done everything correctly
A5: Jan - March, 2025 | F5: 4. Use the 3 helpful tabs (Software, Headcount, Sales) to understand what caused elements of the business caused the biggest variances from the budget
B6: Actual | C6: Actual | D6: Actual | F6: Actual | G6: Budget
A7: Account | B7: 45688 | C7: =EOMONTH(B7,1) -> 45716 | D7: =EOMONTH(C7,1) -> 45747 | F7: Q1-25 | G7: Q1-25 | H7: Change | I7: Change %
A8: Total Headcount | B8: =Headcount!C10 -> 130 | C8: =Headcount!D10 -> 160 | D8: =Headcount!E10 -> 190 | F8: =D8 -> 190
A10: Income
A11: 41001 Sales - Platform Fees | B11: =C11*0.9 -> 1099800 | C11: 1222000 | D11: =C11*1.3 -> 1588600 | F11: =SUM(B11:D11) -> 3910400
A12: 41002 Sales - Transaction Fees | B12: =C12*0.9 -> 853200 | C12: 948000 | D12: =C12*1.3 -> 1232400 | F12: =SUM(B12:D12) -> 3033600
A13: Total Income | B13: =(B11)+(B12) -> 1953000 | C13: =(C11)+(C12) -> 2170000 | D13: =(D11)+(D12) -> 2821000 | F13: =(F11)+(F12) -> 6944000
A14: Cost of Goods Sold
A15: 51000 Cost of Sales
A16: 51001 COS - Server Cost | B16: =C16*0.9 -> 343350 | C16: 381500 | D16: =C16*1.05 -> 400575 | F16: =SUM(B16:D16) -> 1125425
A17: 51002 COS - Customer Support Salaries | B17: =C17*0.9 -> 837000 | C17: 930000 | D17: =C17*1.05 -> 976500 | F17: =SUM(B17:D17) -> 2743500
A18: 51003 Customer Support Medical Insurance | B18: =11484.42 -> 11484.42 | C18: 114844.2 | D18: =C18*1.05 -> 120586.41 | F18: =SUM(B18:D18) -> 246915.03
A19: 51004 Customer Support 401K Match | B19: =1395 -> 1395 | C19: 13950 | D19: =C19*1.05 -> 14647.5 | F19: =SUM(B19:D19) -> 29992.5
A20: 51005 Customer Support Payroll Tax | B20: =7114.5 -> 7114.5 | C20: 71145 | D20: =C20*1.05 -> 74702.25 | F20: =SUM(B20:D20) -> 152961.75
A21: 51006 Customer Support Workers Comp | B21: =189.06 -> 189.06 | C21: 1890.6 | D21: =C21*1.05 -> 1985.13 | F21: =SUM(B21:D21) -> 4064.79
A22: 51007 Customer Support Vacation Expense | B22: =894.23 -> 894.23 | C22: 8942.3 | D22: =C22*1.05 -> 9389.415 | F22: =SUM(B22:D22) -> 19225.945
A23: Total 51000 Cost of Sales | B23: =(((((((B15)+(B16))+(B17))+(B18))+(B19))+(B20))+(B21))+(B22) -> 1201427.2 | C23: =(((((((C15)+(C16))+(C17))+(C18))+(C19))+(C20))+(C21))+(C22) -> 1522272.1 | D23: =(((((((D15)+(D16))+(D17))+(D18))+(D19))+(D20))+(D21))+(D22) -> 1598385.7 | F23: =SUM(B23:D23) -> 4322085
A24: Total Cost of Goods Sold | B24: =B23 -> 1201427.2 | C24: =C23 -> 1522272.1 | D24: =D23 -> 1598385.7 | F24: =SUM(B24:D24) -> 4322085
A25: Gross Profit | B25: =(B13)-(B24) -> 751572.79 | C25: =(C13)-(C24) -> 647727.9 | D25: =(D13)-(D24) -> 1222614.3 | F25: =SUM(B25:D25) -> 2621915
A26: Expenses
A27: 61000 Payroll expenses
A28: 61001 Salaries & Wages | B28: =C28*0.9 -> 3693600 | C28: 4104000 | D28: =C28*1.07 -> 4391280 | F28: =SUM(B28:D28) -> 12188880
A29: 61002 Medical Insurance | B29: =C29*0.9 -> 447892.74 | C29: 497658.6 | D29: =C29*1.07 -> 532494.7 | F29: =SUM(B29:D29) -> 1478046
A30: 61004 Payroll Taxes | B30: =C30*0.9 -> 394923.6 | C30: 438804 | D30: =C30*1.07 -> 469520.28 | F30: =SUM(B30:D30) -> 1303247.9
A31: 61005 Performance Bonus | B31: 130000 | C31: 160000 | D31: 190000 | F31: =SUM(B31:D31) -> 480000
A32: 61006 Commissions | B32: =C32*0.9 -> 17001 | C32: 18890 | D32: =C32*1.07 -> 20212.3 | F32: =SUM(B32:D32) -> 56103.3
A33: 61007 401K Match | B33: =C33*0.9 -> 55404 | C33: 61560 | D33: =C33*1.07 -> 65869.2 | F33: =SUM(B33:D33) -> 182833.2
A34: 61008 Workers Comp Expense | B34: =C34*0.9 -> 7373.7 | C34: 8193 | D34: =C34*1.07 -> 8766.51 | F34: =SUM(B34:D34) -> 24333.21
A35: 61009 Option Expense | B35: =C35*0.9 -> 13041 | C35: 14490 | D35: =C35*1.07 -> 15504.3 | F35: =SUM(B35:D35) -> 43035.3
A36: 61010 Vacation Expense | B36: =C36*0.9 -> 35515.44 | C36: 39461.6 | D36: =C36*1.07 -> 42223.912 | F36: =SUM(B36:D36) -> 117200.95
A37: 61011 Severance Expense | B37: =C37*0.9 -> 180000 | C37: 200000 | D37: =C37*1.07 -> 214000 | F37: =SUM(B37:D37) -> 594000
A38: Total 61000 Payroll expenses | B38: =((((((((((B27)+(B28))+(B29))+(B30))+(B31))+(B32))+(B33))+(B34))+(B35))+(B36))+(B37) -> 4974751.5 | C38: =SUM(C28:C37) -> 5543057.2 | D38: =SUM(D28:D37) -> 5949871.2 | F38: =SUM(F28:F37) -> 16467680
A39: 61013 Travel
A40: 61014 Airfare | B40: =C40*0.9 -> 10800 | C40: 12000 | D40: =C40*1.07 -> 12840 | F40: =SUM(B40:D40) -> 35640
A41: 61015 Hotels | B41: =C41*0.9 -> 70200 | C41: 78000 | D41: =C41*1.07 -> 83460 | F41: =SUM(B41:D41) -> 231660
...

Sheet Answer Key
A2: The Controller Academy
A3: Spa Booker
A4: Profit and Loss
A5: Jan - March, 2025
B6: Actual | C6: Actual | D6: Actual | F6: Actual | G6: Budget
A7: Account | B7: 45688 | C7: =EOMONTH(B7,1) -> 45716 | D7: =EOMONTH(C7,1) -> 45747 | F7: Q1-25 | G7: Q1-25 | H7: Change | I7: Change %
A8: Total Headcount | B8: =Headcount!C10 -> 130 | C8: =Headcount!D10 -> 160 | D8: =Headcount!E10 -> 190 | F8: =D8 -> 190 | G8: ='Budget P&L'!D8 -> 180 | H8: =G8-F8 -> -10 | I8: =H8/G8 -> -0.055555556
A10: Income
A11: 41001 Sales - Platform Fees | B11: =C11*0.9 -> 1099800 | C11: 1222000 | D11: =C11*1.3 -> 1588600 | F11: =SUM(B11:D11) -> 3910400 | G11: =SUM('Budget P&L'!B11:D11) -> 3753984 | H11: =F11-G11 -> 156416 | I11: =H11/G11 -> 0.041666667
A12: 41002 Sales - Transaction Fees | B12: =C12*0.9 -> 853200 | C12: 948000 | D12: =C12*1.3 -> 1232400 | F12: =SUM(B12:D12) -> 3033600 | G12: =SUM('Budget P&L'!B12:D12) -> 2912256 | H12: =F12-G12 -> 121344 | I12: =H12/G12 -> 0.041666667
A13: Total Income | B13: =(B11)+(B12) -> 1953000 | C13: =(C11)+(C12) -> 2170000 | D13: =(D11)+(D12) -> 2821000 | F13: =(F11)+(F12) -> 6944000 | G13: =(G11)+(G12) -> 6666240 | H13: =(H11)+(H12) -> 277760 | I13: =H13/G13 -> 0.041666667
A14: Cost of Goods Sold
A15: 51000 Cost of Sales
A16: 51001 COS - Server Cost | B16: 343350 | C16: 381500 | D16: 400575 | F16: =SUM(B16:D16) -> 1125425 | G16: =SUM('Budget P&L'!B16:D16) -> 1114170.8 | H16: =G16-F16 -> -11254.25 | I16: =H16/G16 -> -0.01010101
A17: 51002 COS - Customer Support Salaries | B17: =C17*0.9 -> 837000 | C17: 930000 | D17: =C17*1.05 -> 976500 | F17: =SUM(B17:D17) -> 2743500 | G17: =SUM('Budget P&L'!B17:D17) -> 2606325 | H17: =G17-F17 -> -137175 | I17: =H17/G17 -> -0.052631579
A18: 51003 Customer Support Medical Insurance | B18: =11484.42 -> 11484.42 | C18: 114844.2 | D18: =C18*1.05 -> 120586.41 | F18: =SUM(B18:D18) -> 246915.03 | G18: =SUM('Budget P&L'!B18:D18) -> 234569.28 | H18: =G18-F18 -> -12345.752 | I18: =H18/G18 -> -0.052631579
A19: 51004 Customer Support 401K Match | B19: =1395 -> 1395 | C19: 13950 | D19: =C19*1.05 -> 14647.5 | F19: =SUM(B19:D19) -> 29992.5 | G19: =SUM('Budget P&L'!B19:D19) -> 28492.875 | H19: =G19-F19 -> -1499.625 | I19: =H19/G19 -> -0.052631579
A20: 51005 Customer Support Payroll Tax | B20: =7114.5 -> 7114.5 | C20: 71145 | D20: =C20*1.05 -> 74702.25 | F20: =SUM(B20:D20) -> 152961.75 | G20: =SUM('Budget P&L'!B20:D20) -> 145313.66 | H20: =G20-F20 -> -7648.0875 | I20: =H20/G20 -> -0.052631579
A21: 51006 Customer Support Workers Comp | B21: =189.06 -> 189.06 | C21: 1890.6 | D21: =C21*1.05 -> 1985.13 | F21: =SUM(B21:D21) -> 4064.79 | G21: =SUM('Budget P&L'!B21:D21) -> 3861.5505 | H21: =G21-F21 -> -203.2395 | I21: =H21/G21 -> -0.052631579
A22: 51007 Customer Support Vacation Expense | B22: =894.23 -> 894.23 | C22: 8942.3 | D22: =C22*1.05 -> 9389.415 | F22: =SUM(B22:D22) -> 19225.945 | G22: =SUM('Budget P&L'!B22:D22) -> 18264.648 | H22: =G22-F22 -> -961.29725 | I22: =H22/G22 -> -0.052631579
A23: Total 51000 Cost of Sales | B23: =(((((((B15)+(B16))+(B17))+(B18))+(B19))+(B20))+(B21))+(B22) -> 1201427.2 | C23: =(((((((C15)+(C16))+(C17))+(C18))+(C19))+(C20))+(C21))+(C22) -> 1522272.1 | D23: =(((((((D15)+(D16))+(D17))+(D18))+(D19))+(D20))+(D21))+(D22) -> 1598385.7 | F23: =SUM(B23:D23) -> 4322085 | G23: =(((((((G15)+(G16))+(G17))+(G18))+(G19))+(G20))+(G21))+(G22) -> 4150997.8 | H23: =(((((((H15)+(H16))+(H17))+(H18))+(H19))+(H20))+(H21))+(H22) -> -171087.25 | I23: =H23/G23 -> -0.041215934
A24: Total Cost of Goods Sold | B24: =B23 -> 1201427.2 | C24: =C23 -> 1522272.1 | D24: =D23 -> 1598385.7 | F24: =SUM(B24:D24) -> 4322085 | G24: =G23 -> 4150997.8 | H24: =H23 -> -171087.25 | I24: =H24/G24 -> -0.041215934
A25: Gross Profit | B25: =(B13)-(B24) -> 751572.79 | C25: =(C13)-(C24) -> 647727.9 | D25: =(D13)-(D24) -> 1222614.3 | F25: =SUM(B25:D25) -> 2621915 | G25: =(G13)-(G24) -> 2515242.2 | H25: =F25-G25 -> 106672.75 | I25: =H25/G25 -> 0.042410527
A26: Expenses
A27: 61000 Payroll expenses
A28: 61001 Salaries & Wages | B28: =C28*0.9 -> 3693600 | C28: 4104000 | D28: =C28*1.07 -> 4391280 | F28: =SUM(B28:D28) -> 12188880 | G28: =SUM('Budget P&L'!B28:D28) -> 11579436 | H28: =G28-F28 -> -609444 | I28: =H28/G28 -> -0.052631579
A29: 61002 Medical Insurance | B29: =C29*0.9 -> 447892.74 | C29: 497658.6 | D29: =C29*1.07 -> 532494.7 | F29: =SUM(B29:D29) -> 1478046 | G29: =SUM('Budget P&L'!B29:D29) -> 1404143.7 | H29: =G29-F29 -> -73902.302 | I29: =H29/G29 -> -0.052631579
A30: 61004 Payroll Taxes | B30: =C30*0.9 -> 394923.6 | C30: 438804 | D30: =C30*1.07 -> 469520.28 | F30: =SUM(B30:D30) -> 1303247.9 | G30: =SUM('Budget P&L'!B30:D30) -> 1238085.5 | H30: =G30-F30 -> -65162.394 | I30: =H30/G30 -> -0.052631579
A31: 61005 Performance Bonus | B31: =B8*1000 -> 130000 | C31: =C8*1000 -> 160000 | D31: =D8*1000 -> 190000 | F31: =SUM(B31:D31) -> 480000 | G31: =SUM('Budget P&L'!B31:D31) -> 456000 | H31: =G31-F31 -> -24000 | I31: =H31/G31 -> -0.052631579
A32: 61006 Commissions | B32: =C32*0.9 -> 17001 | C32: 18890 | D32: =C32*1.07 -> 20212.3 | F32: =SUM(B32:D32) -> 56103.3 | G32: =SUM('Budget P&L'!B32:D32) -> 53298.135 | H32: =G32-F32 -> -2805.165 | I32: =H32/G32 -> -0.052631579
A33: 61007 401K Match | B33: =C33*0.9 -> 55404 | C33: 61560 | D33: =C33*1.07 -> 65869.2 | F33: =SUM(B33:D33) -> 182833.2 | G33: =SUM('Budget P&L'!B33:D33) -> 173691.54 | H33: =G33-F33 -> -9141.66 | I33: =H33/G33 -> -0.052631579
A34: 61008 Workers Comp Expense | B34: =C34*0.9 -> 7373.7 | C34: 8193 | D34: =C34*1.07 -> 8766.51 | F34: =SUM(B34:D34) -> 24333.21 | G34: =SUM('Budget P&L'!B34:D34) -> 23116.549 | H34: =G34-F34 -> -1216.6605 | I34: =H34/G34 -> -0.052631579
A35: 61009 Option Expense | B35: =C35*0.9 -> 13041 | C35: 14490 | D35: =C35*1.07 -> 15504.3 | F35: =SUM(B35:D35) -> 43035.3 | G35: =SUM('Budget P&L'!B35:D35) -> 40883.535 | H35: =G35-F35 -> -2151.765 | I35: =H35/G35 -> -0.052631579
A36: 61010 Vacation Expense | B36: =C36*0.9 -> 35515.44 | C36: 39461.6 | D36: =C36*1.07 -> 42223.912 | F36: =SUM(B36:D36) -> 117200.95 | G36: =SUM('Budget P&L'!B36:D36) -> 111340.9 | H36: =G36-F36 -> -5860.0476 | I36: =H36/G36 -> -0.052631579
A37: 61011 Severance Expense | B37: =C37*0.9 -> 180000 | C37: 200000 | D37: =C37*1.07 -> 214000 | F37: =SUM(B37:D37) -> 594000 | G37: =SUM('Budget P&L'!B37:D37) -> 564300 | H37: =G37-F37 -> -29700 | I37: =H37/G37 -> -0.052631579
A38: Total 61000 Payroll expenses | B38: =((((((((((B27)+(B28))+(B29))+(B30))+(B31))+(B32))+(B33))+(B34))+(B35))+(B36))+(B37) -> 4974751.5 | C38: =SUM(C28:C37) -> 5543057.2 | D38: =SUM(D28:D37) -> 5949871.2 | F38: =SUM(F28:F37) -> 16467680 | G38: =SUM(G28:G37) -> 15644296 | H38: =SUM(H28:H37) -> -823383.99 | I38: =H38/G38 -> -0.052631579
A39: 61013 Travel
A40: 61014 Airfare | B40: =C40*0.9 -> 10800 | C40: 12000 | D40: =C40*1.07 -> 12840 | F40: =SUM(B40:D40) -> 35640 | G40: =SUM('Budget P&L'!B40:D40) -> 37065.6 | H40: =G40-F40 -> 1425.6 | I40: =H40/G40 -> 0.038461538
A41: 61015 Hotels | B41: =C41*0.9 -> 70200 | C41: 78000 | D41: =C41*1.07 -> 83460 | F41: =SUM(B41:D41) -> 231660 | G41: =SUM('Budget P&L'!B41:D41) -> 240926.4 | H41: =G41-F41 -> 9266.4 | I41: =H41/G41 -> 0.038461538
A42: Total 61013 Travel | B42: =((B39)+(B40))+(B41) -> 81000 | C42: =SUM(C40:C41) -> 90000 | D42: =SUM(D40:D41) -> 96300 | F42: =SUM(B42:D42) -> 267300 | G42: =SUM(G40:G41) -> 277992 | H42: =SUM(H40:H41) -> 10692 | I42: =H42/G42 -> 0.038461538
...

Sheet Budget P&L
A2: The Controller Academy
A3: Spa Booker
A4: Budget P&L
A5: 2025
B6: Budget | C6: Budget | D6: Budget | E6: Budget | F6: Budget | G6: Budget | H6: Budget | I6: Budget | J6: Budget | K6: Budget | L6: Budget | M6: Budget | N6: Budget
A7: Account | B7: 45688 | C7: =EOMONTH(B7,1) -> 45716 | D7: =EOMONTH(C7,1) -> 45747 | E7: =EOMONTH(D7,1) -> 45777 | F7: =EOMONTH(E7,1) -> 45808 | G7: =EOMONTH(F7,1) -> 45838 | H7: =EOMONTH(G7,1) -> 45869 | I7: =EOMONTH(H7,1) -> 45900 | J7: =EOMONTH(I7,1) -> 45930 | ... M7: =EOMONTH(L7,1) -> 46022 | N7: 2026
A8: Total Headcount | B8: 125 | C8: 155 | D8: 180 | E8: =D8*1.02 -> 183.6 | F8: =E8*1.02 -> 187.272 | G8: =F8*1.02 -> 191.01744 | H8: =G8*1.02 -> 194.83779 | I8: =H8*1.02 -> 198.73454 | J8: =I8*1.02 -> 202.70924 | K8: =J8*1.02 -> 206.76342 | L8: =K8*1.02 -> 210.89869 | M8: =L8*1.02 -> 215.11666 | N8: =M8 -> 215.11666
A10: Income
A11: 41001 Sales - Platform Fees | B11: ='Answer Key'!B11*0.96 -> 1055808 | C11: ='Answer Key'!C11*0.96 -> 1173120 | D11: ='Answer Key'!D11*0.96 -> 1525056 | E11: 1731574 | F11: 1887415.7 | G11: 2095031.4 | H11: 2325484.8 | I11: 2581288.2 | J11: 2865229.9 | K11: 3180405.1 | L11: 3530249.7 | M11: 3918577.2 | N11: =SUM(B11:M11) -> 27869240
A12: 41002 Sales - Transaction Fees | B12: ='Answer Key'!B12*0.96 -> 819072 | C12: ='Answer Key'!C12*0.96 -> 910080 | D12: ='Answer Key'!D12*0.96 -> 1183104 | E12: 1343316 | F12: 1464214.4 | G12: 1625278 | H12: 1804058.6 | I12: 2002505.1 | J12: 2222780.6 | K12: 2467286.5 | L12: 2738688 | M12: 3039943.7 | N12: =SUM(B12:M12) -> 21620327
A13: Total Income | B13: =(B11)+(B12) -> 1874880 | C13: =(C11)+(C12) -> 2083200 | D13: =(D11)+(D12) -> 2708160 | E13: =(E11)+(E12) -> 3074890 | F13: =(F11)+(F12) -> 3351630.1 | G13: =(G11)+(G12) -> 3720309.4 | H13: =(H11)+(H12) -> 4129543.4 | I13: =(I11)+(I12) -> 4583793.2 | ... N13: =(N11)+(N12) -> 49489567
A14: Cost of Goods Sold
A15: 51000 Cost of Sales
A16: 51001 COS - Server Cost | B16: 339916.5 | C16: 377685 | D16: 396569.25 | E16: 420603.75 | F16: 441633.94 | G16: 463715.63 | H16: 486901.42 | I16: 511246.49 | J16: 536808.81 | K16: 563649.25 | L16: 591831.71 | M16: 621423.3 | N16: =SUM(B16:M16) -> 5751985.1
A17: 51002 COS - Customer Support Salaries | B17: ='Answer Key'!B17*0.95 -> 795150 | C17: ='Answer Key'!C17*0.95 -> 883500 | D17: ='Answer Key'!D17*0.95 -> 927675 | E17: 996030 | F17: 1015950.6 | G17: 1036269.6 | H17: 1056995 | I17: 1078134.9 | J17: 1099697.6 | K17: 1121691.6 | L17: 1144125.4 | M17: 1167007.9 | N17: =SUM(B17:M17) -> 12322228
A18: 51003 Customer Support Medical Insurance | B18: ='Answer Key'!B18*0.95 -> 10910.199 | C18: ='Answer Key'!C18*0.95 -> 109101.99 | D18: ='Answer Key'!D18*0.95 -> 114557.09 | E18: 126615.73 | F18: 132946.52 | G18: 139593.84 | H18: 146573.54 | I18: 153902.21 | J18: 161597.32 | K18: 169677.19 | L18: 178161.05 | M18: 187069.1 | N18: =SUM(B18:M18) -> 1630705.8
A19: 51004 Customer Support 401K Match | B19: ='Answer Key'!B19*0.95 -> 1325.25 | C19: ='Answer Key'!C19*0.95 -> 13252.5 | D19: ='Answer Key'!D19*0.95 -> 13915.125 | E19: 15379.875 | F19: 16148.869 | G19: 16956.312 | H19: 17804.128 | I19: 18694.334 | J19: 19629.051 | K19: 20610.503 | L19: 21641.029 | M19: 22723.08 | N19: =SUM(B19:M19) -> 198080.06
A20: 51005 Customer Support Payroll Tax | B20: ='Answer Key'!B20*0.95 -> 6758.775 | C20: ='Answer Key'!C20*0.95 -> 67587.75 | D20: ='Answer Key'!D20*0.95 -> 70967.137 | E20: 78437.363 | F20: 82359.231 | G20: 86477.192 | H20: 90801.052 | I20: 95341.104 | J20: 100108.16 | K20: 105113.57 | L20: 110369.25 | M20: 115887.71 | N20: =SUM(B20:M20) -> 1010208.3
A21: 51006 Customer Support Workers Comp | B21: ='Answer Key'!B21*0.95 -> 179.607 | C21: ='Answer Key'!C21*0.95 -> 1796.07 | D21: ='Answer Key'!D21*0.95 -> 1885.8735 | E21: 2084.3865 | F21: 2188.6058 | G21: 2298.0361 | H21: 2412.9379 | I21: 2533.5848 | J21: 2660.2641 | K21: 2793.2773 | L21: 2932.9411 | M21: 3079.5882 | N21: =SUM(B21:M21) -> 26845.172
A22: 51007 Customer Support Vacation Expense | B22: ='Answer Key'!B22*0.95 -> 849.5185 | C22: ='Answer Key'!C22*0.95 -> 8495.185 | D22: ='Answer Key'!D22*0.95 -> 8919.9442 | E22: 9858.8857 | F22: 10351.83 | G22: 10869.422 | H22: 11412.893 | I22: 11983.537 | J22: 12582.714 | K22: 13211.85 | L22: 13872.442 | M22: 14566.064 | N22: =SUM(B22:M22) -> 126974.29
A23: Total 51000 Cost of Sales | B23: =(((((((B15)+(B16))+(B17))+(B18))+(B19))+(B20))+(B21))+(B22) -> 1155089.8 | C23: =(((((((C15)+(C16))+(C17))+(C18))+(C19))+(C20))+(C21))+(C22) -> 1461418.5 | D23: =(((((((D15)+(D16))+(D17))+(D18))+(D19))+(D20))+(D21))+(D22) -> 1534489.4 | E23: =(((((((E15)+(E16))+(E17))+(E18))+(E19))+(E20))+(E21))+(E22) -> 1649010 | F23: =(((((((F15)+(F16))+(F17))+(F18))+(F19))+(F20))+(F21))+(F22) -> 1701579.6 | G23: =(((((((G15)+(G16))+(G17))+(G18))+(G19))+(G20))+(G21))+(G22) -> 1756180.1 | H23: =(((((((H15)+(H16))+(H17))+(H18))+(H19))+(H20))+(H21))+(H22) -> 1812901 | I23: =(((((((I15)+(I16))+(I17))+(I18))+(I19))+(I20))+(I21))+(I22) -> 1871836.2 | ... N23: =(((((((N15)+(N16))+(N17))+(N18))+(N19))+(N20))+(N21))+(N22) -> 21067026
A24: Total Cost of Goods Sold | B24: =B23 -> 1155089.8 | C24: =C23 -> 1461418.5 | D24: =D23 -> 1534489.4 | E24: =E23 -> 1649010 | F24: =F23 -> 1701579.6 | G24: =G23 -> 1756180.1 | H24: =H23 -> 1812901 | I24: =I23 -> 1871836.2 | ... N24: =N23 -> 21067026
A25: Gross Profit | B25: =(B13)-(B24) -> 719790.15 | C25: =(C13)-(C24) -> 621781.5 | D25: =(D13)-(D24) -> 1173670.6 | E25: =(E13)-(E24) -> 1425880 | F25: =(F13)-(F24) -> 1650050.5 | G25: =(G13)-(G24) -> 1964129.4 | H25: =(H13)-(H24) -> 2316642.5 | I25: =(I13)-(I24) -> 2711957.1 | ... N25: =(N13)-(N24) -> 28422541
A26: Expenses
A27: 61000 Payroll expenses
A28: 61001 Salaries & Wages | B28: ='Answer Key'!B28*0.95 -> 3508920 | C28: ='Answer Key'!C28*0.95 -> 3898800 | D28: ='Answer Key'!D28*0.95 -> 4171716 | E28: 4479983.9 | F28: 4570479.5 | G28: 4662803.2 | H28: 4756991.8 | I28: 4853083.1 | J28: 4951115.4 | K28: 5051127.9 | L28: 5153160.7 | M28: 5257254.5 | N28: =SUM(B28:M28) -> 55315436
A29: 61002 Medical Insurance | B29: ='Answer Key'!B29*0.95 -> 425498.1 | C29: ='Answer Key'!C29*0.95 -> 472775.67 | D29: ='Answer Key'!D29*0.95 -> 505869.97 | E29: 543251.09 | F29: 554224.77 | G29: 565420.11 | H29: 576841.59 | I29: 588493.79 | J29: 600381.37 | K29: 612509.07 | L29: 624881.76 | M29: 637504.37 | N29: =SUM(B29:M29) -> 6707651.7
A30: 61004 Payroll Taxes | B30: ='Answer Key'!B30*0.95 -> 375177.42 | C30: ='Answer Key'!C30*0.95 -> 416863.8 | D30: ='Answer Key'!D30*0.95 -> 446044.27 | E30: 479004.59 | F30: 488680.48 | G30: 498551.83 | H30: 508622.58 | I30: 518896.75 | J30: 529378.47 | K30: 540071.91 | L30: 550981.36 | M30: 562111.19 | N30: =SUM(B30:M30) -> 5914384.6
A31: 61005 Performance Bonus | B31: ='Answer Key'!B31*0.95 -> 123500 | C31: ='Answer Key'!C31*0.95 -> 152000 | D31: ='Answer Key'!D31*0.95 -> 180500 | E31: 193838 | F31: 197753.53 | G31: 201748.15 | H31: 205823.46 | I31: 209981.1 | J31: 214222.71 | K31: 218550.01 | L31: 222964.72 | M31: 227468.61 | N31: =SUM(B31:M31) -> 2348350.3
A32: 61006 Commissions | B32: ='Answer Key'!B32*0.95 -> 16150.95 | C32: ='Answer Key'!C32*0.95 -> 17945.5 | D32: ='Answer Key'!D32*0.95 -> 19201.685 | E32: 20620.588 | F32: 21037.124 | G32: 21462.074 | H32: 21895.608 | I32: 22337.899 | J32: 22789.125 | K32: 23249.465 | L32: 23719.105 | M32: 24198.23 | N32: =SUM(B32:M32) -> 254607.36
A33: 61007 401K Match | B33: ='Answer Key'!B33*0.95 -> 52633.8 | C33: ='Answer Key'!C33*0.95 -> 58482 | D33: ='Answer Key'!D33*0.95 -> 62575.74 | E33: 67199.758 | F33: 68557.193 | G33: 69942.048 | H33: 71354.878 | I33: 72796.246 | J33: 74266.73 | K33: 75766.918 | L33: 77297.41 | M33: 78858.818 | N33: =SUM(B33:M33) -> 829731.54
A34: 61008 Workers Comp Expense | B34: ='Answer Key'!B34*0.95 -> 7005.015 | C34: ='Answer Key'!C34*0.95 -> 7783.35 | D34: ='Answer Key'!D34*0.95 -> 8328.1845 | E34: 8943.5935 | F34: 9124.2541 | G34: 9308.564 | H34: 9496.597 | I34: 9688.4283 | J34: 9884.1345 | K34: 10083.794 | L34: 10287.487 | M34: 10495.294 | N34: =SUM(B34:M34) -> 110428.7
A35: 61009 Option Expense | B35: ='Answer Key'!B35*0.95 -> 12388.95 | C35: ='Answer Key'!C35*0.95 -> 13765.5 | D35: ='Answer Key'!D35*0.95 -> 14729.085 | E35: 15817.487 | F35: 16137 | G35: 16462.967 | H35: 16795.519 | I35: 17134.789 | J35: 17480.912 | K35: 17834.026 | L35: 18194.273 | M35: 18561.798 | N35: =SUM(B35:M35) -> 195302.31
A36: 61010 Vacation Expense | B36: ='Answer Key'!B36*0.95 -> 33739.668 | C36: ='Answer Key'!C36*0.95 -> 37488.52 | D36: ='Answer Key'!D36*0.95 -> 40112.716 | E36: 43076.835 | F36: 43946.987 | G36: 44834.716 | H36: 45740.377 | I36: 46664.333 | J36: 47606.953 | K36: 48568.613 | L36: 49549.699 | M36: 50550.603 | N36: =SUM(B36:M36) -> 531880.02
A37: 61011 Severance Expense | B37: ='Answer Key'!B37*0.95 -> 171000 | C37: ='Answer Key'!C37*0.95 -> 190000 | D37: ='Answer Key'!D37*0.95 -> 203300 | E37: 218322.8 | F37: 222732.92 | G37: 227232.13 | H37: 231822.21 | I37: 236505.02 | J37: 241282.42 | K37: 246156.33 | L37: 251128.69 | M37: 256201.49 | N37: =SUM(B37:M37) -> 2695684
A38: Total 61000 Payroll expenses | B38: =((((((((((B27)+(B28))+(B29))+(B30))+(B31))+(B32))+(B33))+(B34))+(B35))+(B36))+(B37) -> 4726013.9 | C38: =SUM(C28:C37) -> 5265904.3 | D38: =SUM(D28:D37) -> 5652377.6 | E38: =SUM(E28:E37) -> 6070058.6 | F38: =SUM(F28:F37) -> 6192673.8 | G38: =SUM(G28:G37) -> 6317765.8 | H38: =SUM(H28:H37) -> 6445384.7 | I38: =SUM(I28:I37) -> 6575581.4 | J38: =SUM(J28:J37) -> 6708408.2 | ... N38: =SUM(N28:N37) -> 74903456
A39: 61013 Travel
A40: 61014 Airfare | B40: ='Answer Key'!B40*1.04 -> 11232 | C40: ='Answer Key'!C40*1.04 -> 12480 | D40: ='Answer Key'!D40*1.04 -> 13353.6 | E40: 13482 | F40: 14156.1 | G40: 14863.905 | H40: 15607.1 | I40: 16387.455 | J40: 17206.828 | K40: 18067.169 | L40: 18970.528 | M40: 19919.054 | N40: =SUM(B40:M40) -> 185725.74
A41: 61015 Hotels | B41: ='Answer Key'!B41*1.04 -> 73008 | C41: ='Answer Key'!C41*1.04 -> 81120 | D41: ='Answer Key'!D41*1.04 -> 86798.4 | E41: 87633 | F41: 92014.65 | G41: 96615.383 | H41: 101446.15 | I41: 106518.46 | J41: 111844.38 | K41: 117436.6 | L41: 123308.43 | M41: 129473.85 | N41: =SUM(B41:M41) -> 1207217.3
A42: Total 61013 Travel | B42: =((B39)+(B40))+(B41) -> 84240 | C42: =SUM(C40:C41) -> 93600 | D42: =SUM(D40:D41) -> 100152 | E42: =SUM(E40:E41) -> 101115 | F42: =SUM(F40:F41) -> 106170.75 | G42: =SUM(G40:G41) -> 111479.29 | H42: =SUM(H40:H41) -> 117053.25 | I42: =SUM(I40:I41) -> 122905.91 | J42: =SUM(J40:J41) -> 129051.21 | ... N42: =SUM(N40:N41) -> 1392943.1
...

Sheet Software Budget
B4: Budget
B5: Tool | C5: 45688 | D5: =EOMONTH(C5,1) -> 45716 | E5: =EOMONTH(D5,1) -> 45747 | F5: =EOMONTH(E5,1) -> 45777 | G5: =EOMONTH(F5,1) -> 45808 | H5: =EOMONTH(G5,1) -> 45838 | I5: =EOMONTH(H5,1) -> 45869 | J5: =EOMONTH(I5,1) -> 45900 | K5: =EOMONTH(J5,1) -> 45930 | ... N5: =EOMONTH(M5,1) -> 46022
B6: Salesforce | C6: 8880 | D6: 9412.8 | E6: 9977.568 | F6: 10576.222 | G6: 11210.795 | H6: 11883.443 | I6: 12596.45 | J6: 13352.237 | K6: 14153.371 | L6: 15002.573 | M6: 15902.728 | N6: 16856.891
B7: HubSpot | C7: 3000 | D7: 3180 | E7: 3370.8 | F7: 3573.048 | G7: 3787.4309 | H7: 4014.6767 | I7: 4255.5573 | J7: 4510.8908 | K7: 4781.5442 | L7: 5068.4369 | M7: 5372.5431 | N7: 5694.8957
B8: Stripe | C8: 2500 | D8: 2500 | E8: 2500 | F8: 2500 | G8: 2500 | H8: 2500 | I8: 2500 | J8: 2500 | K8: 2500 | L8: 2500 | M8: 2500 | N8: 2500
B9: Zendesk | C9: 3900 | D9: 3900 | E9: 3900 | F9: 3900 | G9: 3900 | H9: 3900 | I9: 3900 | J9: 3900 | K9: 3900 | L9: 3900 | M9: 3900 | N9: 3900
B10: Slack | C10: 5900 | D10: 5900 | E10: 5900 | F10: 5900 | G10: 5900 | H10: 5900 | I10: 5900 | J10: 5900 | K10: 5900 | L10: 5900 | M10: 5900 | N10: 5900
B11: Jira | C11: 4500 | D11: 4500 | E11: 4500 | F11: 4500 | G11: 4500 | H11: 4500 | I11: 4500 | J11: 4500 | K11: 4500 | L11: 4500 | M11: 4500 | N11: 4500
B12: GitHub | C12: 4900 | D12: 4900 | E12: 4900 | F12: 4900 | G12: 4900 | H12: 4900 | I12: 4900 | J12: 4900 | K12: 4900 | L12: 4900 | M12: 4900 | N12: 4900
B13: Docusign | C13: 4000 | D13: 4000 | E13: 4000 | F13: 4000 | G13: 4000 | H13: 4000 | I13: 4000 | J13: 4000 | K13: 4000 | L13: 4000 | M13: 4000 | N13: 4000
B14: Mixpanel | C14: 6800 | D14: 6800 | E14: 6800 | F14: 6800 | G14: 6800 | H14: 6800 | I14: 6800 | J14: 6800 | K14: 6800 | L14: 6800 | M14: 6800 | N14: 6800
B15: ActivTrak | C15: 6900 | D15: 6900 | E15: 6900 | F15: 6900 | G15: 6900 | H15: 6900 | I15: 6900 | J15: 6900 | K15: 6900 | L15: 6900 | M15: 6900 | N15: 6900
B16: Confluence | C16: 3800 | D16: 3800 | E16: 3800 | F16: 3800 | G16: 3800 | H16: 3800 | I16: 3800 | J16: 3800 | K16: 3800 | L16: 3800 | M16: 3800 | N16: 3800
B17: New Tool - Placeholder | D17: 5407.2 | E17: 8935.632 | F17: 12718.61 | G17: 16774.405 | H17: 21122.596 | I17: 25784.159 | J17: 30781.57 | K17: 36138.911 | L17: 41881.984 | M17: 48038.433 | N17: 54637.876
B19: Total | C19: =SUM(C6:C17) -> 55080 | D19: =SUM(D6:D17) -> 61200 | E19: =SUM(E6:E17) -> 65484 | F19: =SUM(F6:F17) -> 70067.88 | G19: =SUM(G6:G17) -> 74972.632 | H19: =SUM(H6:H17) -> 80220.716 | I19: =SUM(I6:I17) -> 85836.166 | J19: =SUM(J6:J17) -> 91844.698 | ... N19: =SUM(N6:N17) -> 120389.66

Sheet Profit and Loss
A2: This file is part of the Controller Academy Course
A3: Spa Booker
A4: Profit and Loss
A5: March, 2022
F6: Comment required for changes over 10%
A7: Account | B7: Actual | C7: Budget | D7: Var $ | E7: Var % | F7: Comment
A8: Total Headcount | B8: =Headcount!#REF! -> #REF! | C8: 34 | D8: =B8-C8 -> #REF! | E8: =D8/C8 -> #REF! | F8: Hiring is ahead of plan (see tab "Headcount")
A10: Income
A11: 41001 Sales - Platform Fees | B11: =122200 -> 122200 | C11: 136620 | D11: =B11-C11 -> -14420 | E11: =D11/B11 -> -0.11800327 | F11: Slight lag vs budget due to less stores signing up than planned
A12: 41002 Sales - Transaction Fees | B12: =94800 -> 94800 | C12: 91080 | D12: =B12-C12 -> 3720 | E12: =D12/B12 -> 0.039240506
A13: Total Income | B13: =(B11)+(B12) -> 217000 | C13: 227700 | D13: =B13-C13 -> -10700 | E13: =D13/B13 -> -0.049308756
A14: Cost of Goods Sold
A15: 51000 Cost of Sales
A16: 51001 COS - Server Cost | B16: =38150 -> 38150 | C16: 40000 | D16: =B16-C16 -> -1850 | E16: =D16/B16 -> -0.048492792 | F16: Inline with difference in revenue
A17: 51002 COS - Customer Support Salaries | B17: =93000 -> 93000 | C17: 81840 | D17: =B17-C17 -> 11160 | E17: =D17/B17 -> 0.12 | F17: Headcount ahead of plan by 12%
A18: 51003 Customer Support Medical Insurance | B18: =11484.42 -> 11484.42 | C18: 10106.29 | D18: =B18-C18 -> 1378.1304 | E18: =D18/B18 -> 0.12 | F18: Headcount ahead of plan by 12%
A19: 51004 Customer Support 401K Match | B19: =1395 -> 1395 | C19: 1227.6 | D19: =B19-C19 -> 167.4 | E19: =D19/B19 -> 0.12 | F19: Headcount ahead of plan by 12%
A20: 51005 Customer Support Payroll Tax | B20: =7114.5 -> 7114.5 | C20: 6260.76 | D20: =B20-C20 -> 853.74 | E20: =D20/B20 -> 0.12 | F20: Headcount ahead of plan by 12%
A21: 51006 Customer Support Workers Comp | B21: =189.06 -> 189.06 | C21: 166.3728 | D21: =B21-C21 -> 22.6872 | E21: =D21/B21 -> 0.12 | F21: Headcount ahead of plan by 12%
A22: 51007 Customer Support Vacation Expense | B22: =894.23 -> 894.23 | C22: 786.9224 | D22: =B22-C22 -> 107.3076 | E22: =D22/B22 -> 0.12 | F22: Headcount ahead of plan by 12%
A23: Total 51000 Cost of Sales | B23: =(((((((B15)+(B16))+(B17))+(B18))+(B19))+(B20))+(B21))+(B22) -> 152227.21 | C23: 140387.94 | D23: =(((((((D15)+(D16))+(D17))+(D18))+(D19))+(D20))+(D21))+(D22) -> 11839.265
A24: Total Cost of Goods Sold | B24: =B23 -> 152227.21 | C24: 140387.94 | D24: =D23 -> 11839.265
A25: Gross Profit | B25: =(B13)-(B24) -> 64772.79 | C25: 87312.055 | D25: =(D13)-(D24) -> -22539.265
A26: Expenses
A27: 61000 Payroll expenses
A28: 61001 Salaries & Wages | B28: =410400 -> 410400 | C28: 361152 | D28: =B28-C28 -> 49248 | E28: =D28/B28 -> 0.12 | F28: increase is inline with increase in headcount
A29: 61002 Medical Insurance | B29: =49765.86 -> 49765.86 | C29: 43793.957 | D29: =B29-C29 -> 5971.9032 | E29: =D29/B29 -> 0.12 | F29: increase is inline with increase in headcount
A30: 61004 Payroll Taxes | B30: =43880.4 -> 43880.4 | C30: 38614.752 | D30: =B30-C30 -> 5265.648 | E30: =D30/B30 -> 0.12 | F30: increase is inline with increase in headcount
A31: 61005 Performance Bonus | B31: =0 -> 0 | C31: 0 | D31: =B31-C31 -> 0 | E31: 0
A32: 61006 Commissions | B32: =1889 -> 1889 | C32: 1662.32 | D32: =B32-C32 -> 226.68 | E32: =D32/B32 -> 0.12
A33: 61007 401K Match | B33: =6156 -> 6156 | C33: 5417.28 | D33: =B33-C33 -> 738.72 | E33: =D33/B33 -> 0.12 | F33: increase is inline with increase in headcount
A34: 61008 Workers Comp Expense | B34: =819.3 -> 819.3 | C34: 720.984 | D34: =B34-C34 -> 98.316 | E34: =D34/B34 -> 0.12 | F34: increase is inline with increase in headcount
A35: 61009 Option Expense | B35: =1449 -> 1449 | C35: 1275.12 | D35: =B35-C35 -> 173.88 | E35: =D35/B35 -> 0.12
A36: 61010 Vacation Expense | B36: =3946.16 -> 3946.16 | C36: 3472.6208 | D36: =B36-C36 -> 473.5392 | E36: =D36/B36 -> 0.12 | F36: increase is inline with increase in headcount
A37: 61011 Severance Expense | B37: =20000 -> 20000 | C37: 0 | D37: =B37-C37 -> 20000 | E37: =D37/B37 -> 1 | F37: Unplanned severance
A38: Total 61000 Payroll expenses | B38: =((((((((((B27)+(B28))+(B29))+(B30))+(B31))+(B32))+(B33))+(B34))+(B35))+(B36))+(B37) -> 538305.72 | C38: 456109.03
A39: 61013 Travel
A40: 61014 Airfare | B40: =1200 -> 1200 | C40: 1140 | D40: =B40-C40 -> 60 | E40: =D40/B40 -> 0.05
A41: 61015 Hotels | B41: =7800 -> 7800 | C41: 7410 | D41: =B41-C41 -> 390 | E41: =D41/B41 -> 0.05
A42: Total 61013 Travel | B42: =((B39)+(B40))+(B41) -> 9000 | C42: 8550
...

Sheet Headcount
B3: Headcount Data - Actual
B4: Department | C4: 45688 | D4: =EOMONTH(C4,1) -> 45716 | E4: =EOMONTH(D4,1) -> 45747
B5: Customer Support | C5: 25 | D5: 30 | E5: 35
B6: R&D | C6: 40 | D6: 50 | E6: 60
B7: G&A | C7: 25 | D7: 30 | E7: 35
B8: S&M | C8: 40 | D8: 50 | E8: 60
B10: Total | C10: =SUM(C5:C9) -> 130 | D10: =SUM(D5:D9) -> 160 | E10: =SUM(E5:E9) -> 190
B12: Headcount Data - Budget
B13: Department | C13: 45688 | D13: =EOMONTH(C13,1) -> 45716 | E13: =EOMONTH(D13,1) -> 45747
B14: Customer Support | C14: 22 | D14: 27 | E14: 30
B15: R&D | C15: 40 | D15: 50 | E15: 58
B16: G&A | C16: 23 | D16: 28 | E16: 33
B17: S&M | C17: 40 | D17: 50 | E17: 59
B19: Total | C19: =SUM(C14:C18) -> 125 | D19: =SUM(D14:D18) -> 155 | E19: =SUM(E14:E18) -> 180
B21: Difference % | C21: =(C10-C19)/C19 -> 0.04 | D21: =(D10-D19)/D19 -> 0.032258065 | E21: =(E10-E19)/E19 -> 0.055555556

Sheet Sales by Customer Summary 
A1: Actual | G1: Budget
A2: Sales by Customer Summary | G2: Sales by Customer Summary
A3: January - March, 2025 | G3: January - March, 2025
E4: Actual | K4: Budget
B5: 45688 | C5: =EOMONTH(B5,1) -> 45716 | D5: =EOMONTH(C5,1) -> 45747 | E5: Q1-25 | H5: 45688 | I5: =EOMONTH(H5,1) -> 45716 | J5: =EOMONTH(I5,1) -> 45747 | K5: Q1-25
A6: Account-dracula Inc. | B6: 66720 | C6: 77472 | D6: 93600 | E6: =((B6)+(C6))+(D6) -> 237792 | G6: Account-dracula Inc. | H6: 64051.2 | I6: 74373.12 | J6: 89856 | K6: =((H6)+(I6))+(J6) -> 228280.32
A7: Amazin Skins LLC | B7: 182400 | C7: 198000 | D7: 250000 | E7: =((B7)+(C7))+(D7) -> 630400 | G7: Amazin Skins LLC | H7: 175104 | I7: 190080 | J7: 240000 | K7: =((H7)+(I7))+(J7) -> 605184
A8: CustomersRus LLC | B8: 179280 | C8: 148800 | D8: 196800 | E8: =((B8)+(C8))+(D8) -> 524880 | G8: CustomersRus LLC | H8: 172108.8 | I8: 142848 | J8: 188928 | K8: =((H8)+(I8))+(J8) -> 503884.8
A9: Heavyinvoicer LLC | B9: 216000 | C9: 286800 | D9: 309600 | E9: =((B9)+(C9))+(D9) -> 812400 | G9: Heavyinvoicer LLC | H9: 207360 | I9: 275328 | J9: 297216 | K9: =((H9)+(I9))+(J9) -> 779904
A10: InnoVate LLC | B10: 88236 | C10: 154800 | D10: 300000 | E10: =((B10)+(C10))+(D10) -> 543036 | G10: InnoVate LLC | H10: 84706.56 | I10: 148608 | J10: 288000 | K10: =((H10)+(I10))+(J10) -> 521314.56
A11: Maple Leaf Inc. | B11: 146136 | C11: 218400 | D11: 350600 | E11: =((B11)+(C11))+(D11) -> 715136 | G11: Maple Leaf Inc. | H11: 140290.56 | I11: 209664 | J11: 336576 | K11: =((H11)+(I11))+(J11) -> 686530.56
A12: MountainMan Inc. | B12: 195228 | C12: 195328 | D12: 309600 | E12: =((B12)+(C12))+(D12) -> 700156 | G12: MountainMan Inc. | H12: 187418.88 | I12: 187514.88 | J12: 297216 | K12: =((H12)+(I12))+(J12) -> 672149.76
A13: RDP Inc. | B13: 200000 | C13: 211200 | D13: 220800 | E13: =((B13)+(C13))+(D13) -> 632000 | G13: RDP Inc. | H13: 192000 | I13: 202752 | J13: 211968 | K13: =((H13)+(I13))+(J13) -> 606720
A14: TimeCatcher LLC | B14: 179000 | C14: 172800 | D14: 210000 | E14: =((B14)+(C14))+(D14) -> 561800 | G14: TimeCatcher LLC | H14: 171840 | I14: 165888 | J14: 201600 | K14: =((H14)+(I14))+(J14) -> 539328
A15: WordSmither | B15: 500000 | C15: 506400 | D15: 580000 | E15: =((B15)+(C15))+(D15) -> 1586400 | G15: WordSmither | H15: 480000 | I15: 486144 | J15: 556800 | K15: =((H15)+(I15))+(J15) -> 1522944
A16: TOTAL | B16: =(((((((((B6)+(B7))+(B8))+(B9))+(B10))+(B11))+(B12))+(B13))+(B14))+(B15) -> 1953000 | C16: =(((((((((C6)+(C7))+(C8))+(C9))+(C10))+(C11))+(C12))+(C13))+(C14))+(C15) -> 2170000 | D16: =(((((((((D6)+(D7))+(D8))+(D9))+(D10))+(D11))+(D12))+(D13))+(D14))+(D15) -> 2821000 | E16: =((B16)+(C16))+(D16) -> 6944000 | G16: TOTAL | H16: =(((((((((H6)+(H7))+(H8))+(H9))+(H10))+(H11))+(H12))+(H13))+(H14))+(H15) -> 1874880 | I16: =(((((((((I6)+(I7))+(I8))+(I9))+(I10))+(I11))+(I12))+(I13))+(I14))+(I15) -> 2083200 | J16: =(((((((((J6)+(J7))+(J8))+(J9))+(J10))+(J11))+(J12))+(J13))+(J14))+(J15) -> 2708160 | K16: =((H16)+(I16))+(J16) -> 6666240
